INFO       - 2025-01-12 21:56:35,092 - client          : logging in using static token
INFO       - 2025-01-12 21:56:35,939 - gateway         : Shard ID None has connected to Gateway (Session ID: 177313af3ac837e81d6bbdcc4e8874cc).
ERROR      - 2025-01-12 21:56:41,897 - tree            : Ignoring exception in command 'send_reminder'
Traceback (most recent call last):
  File "C:\Users\asmeu\AppData\Local\Packages\PythonSoftwareFoundation.Python.3.11_qbz5n2kfra8p0\LocalCache\local-packages\Python311\site-packages\discord\app_commands\commands.py", line 857, in _do_call
    return await self._callback(self.binding, interaction, **params)  # type: ignore
           ^^^^^^^^^^^^^^^^^^^^^^^^^^^^^^^^^^^^^^^^^^^^^^^^^^^^^^^^^
  File "c:\Projects\NudgeBot\cogs\reminder.py", line 94, in send_reminder
    await interaction.response.send_message(f"@{user.name} Don't forget about your goal: {description}!")
                                                ^^^^^^^^^
AttributeError: 'NoneType' object has no attribute 'name'

The above exception was the direct cause of the following exception:

Traceback (most recent call last):
  File "C:\Users\asmeu\AppData\Local\Packages\PythonSoftwareFoundation.Python.3.11_qbz5n2kfra8p0\LocalCache\local-packages\Python311\site-packages\discord\app_commands\tree.py", line 1310, in _call
    await command._invoke_with_namespace(interaction, namespace)
  File "C:\Users\asmeu\AppData\Local\Packages\PythonSoftwareFoundation.Python.3.11_qbz5n2kfra8p0\LocalCache\local-packages\Python311\site-packages\discord\app_commands\commands.py", line 883, in _invoke_with_namespace
    return await self._do_call(interaction, transformed_values)
           ^^^^^^^^^^^^^^^^^^^^^^^^^^^^^^^^^^^^^^^^^^^^^^^^^^^^
  File "C:\Users\asmeu\AppData\Local\Packages\PythonSoftwareFoundation.Python.3.11_qbz5n2kfra8p0\LocalCache\local-packages\Python311\site-packages\discord\app_commands\commands.py", line 876, in _do_call
    raise CommandInvokeError(self, e) from e
discord.app_commands.errors.CommandInvokeError: Command 'send_reminder' raised an exception: AttributeError: 'NoneType' object has no attribute 'name'
ERROR      - 2025-01-12 21:57:22,123 - tree            : Ignoring exception in command 'send_reminder'
Traceback (most recent call last):
  File "C:\Users\asmeu\AppData\Local\Packages\PythonSoftwareFoundation.Python.3.11_qbz5n2kfra8p0\LocalCache\local-packages\Python311\site-packages\discord\app_commands\commands.py", line 857, in _do_call
    return await self._callback(self.binding, interaction, **params)  # type: ignore
           ^^^^^^^^^^^^^^^^^^^^^^^^^^^^^^^^^^^^^^^^^^^^^^^^^^^^^^^^^
  File "c:\Projects\NudgeBot\cogs\reminder.py", line 95, in send_reminder
    await interaction.response.send_message(f"@{user.name} Don't forget about your goal: {description}!")
                                                ^^^^^^^^^
AttributeError: 'NoneType' object has no attribute 'name'

The above exception was the direct cause of the following exception:

Traceback (most recent call last):
  File "C:\Users\asmeu\AppData\Local\Packages\PythonSoftwareFoundation.Python.3.11_qbz5n2kfra8p0\LocalCache\local-packages\Python311\site-packages\discord\app_commands\tree.py", line 1310, in _call
    await command._invoke_with_namespace(interaction, namespace)
  File "C:\Users\asmeu\AppData\Local\Packages\PythonSoftwareFoundation.Python.3.11_qbz5n2kfra8p0\LocalCache\local-packages\Python311\site-packages\discord\app_commands\commands.py", line 883, in _invoke_with_namespace
    return await self._do_call(interaction, transformed_values)
           ^^^^^^^^^^^^^^^^^^^^^^^^^^^^^^^^^^^^^^^^^^^^^^^^^^^^
  File "C:\Users\asmeu\AppData\Local\Packages\PythonSoftwareFoundation.Python.3.11_qbz5n2kfra8p0\LocalCache\local-packages\Python311\site-packages\discord\app_commands\commands.py", line 876, in _do_call
    raise CommandInvokeError(self, e) from e
discord.app_commands.errors.CommandInvokeError: Command 'send_reminder' raised an exception: AttributeError: 'NoneType' object has no attribute 'name'
